2025-08-15 15:31:00,275 - asyncio - ERROR - Task exception was never retrieved
future: <Task finished name='Task-5' coro=<visual_generation() done, defined at C:\Users\pc\Desktop\projects\intern\backup\kira_backend\app\repeated_tasks\visuals.py:31> exception=ValueError('Missing key inputs argument! To use the Google AI API, provide (`api_key`) arguments. To use the Google Cloud API, provide (`vertexai`, `project` & `location`) arguments.')>
Traceback (most recent call last):
  File "C:\Users\pc\Desktop\projects\intern\backup\kira_backend\app\repeated_tasks\visuals.py", line 42, in visual_generation
    gemini_role_prompt = f.read()
     ^^^^^^^^^^^^^^
  File "C:\Users\pc\anaconda3\envs\image_classification\Lib\site-packages\google\genai\client.py", line 219, in __init__
    self._api_client = self._get_api_client(
                       ^^^^^^^^^^^^^^^^^^^^^
  File "C:\Users\pc\anaconda3\envs\image_classification\Lib\site-packages\google\genai\client.py", line 265, in _get_api_client
    return BaseApiClient(
           ^^^^^^^^^^^^^^
  File "C:\Users\pc\anaconda3\envs\image_classification\Lib\site-packages\google\genai\_api_client.py", line 658, in __init__
    raise ValueError(
ValueError: Missing key inputs argument! To use the Google AI API, provide (`api_key`) arguments. To use the Google Cloud API, provide (`vertexai`, `project` & `location`) arguments.
